2023-11-22T00:24:53.1938212Z ##[group]Run python3 --version
2023-11-22T00:24:53.1938688Z [36;1mpython3 --version[0m
2023-11-22T00:24:53.1939209Z [36;1mpython3 generate_images.py[0m
2023-11-22T00:24:53.2000565Z shell: /usr/bin/bash -e {0}
2023-11-22T00:24:53.2000982Z env:
2023-11-22T00:24:53.2001383Z   pythonLocation: /opt/hostedtoolcache/Python/3.8.18/x64
2023-11-22T00:24:53.2002134Z   PKG_CONFIG_PATH: /opt/hostedtoolcache/Python/3.8.18/x64/lib/pkgconfig
2023-11-22T00:24:53.2002753Z   Python_ROOT_DIR: /opt/hostedtoolcache/Python/3.8.18/x64
2023-11-22T00:24:53.2003327Z   Python2_ROOT_DIR: /opt/hostedtoolcache/Python/3.8.18/x64
2023-11-22T00:24:53.2003973Z   Python3_ROOT_DIR: /opt/hostedtoolcache/Python/3.8.18/x64
2023-11-22T00:24:53.2004566Z   LD_LIBRARY_PATH: /opt/hostedtoolcache/Python/3.8.18/x64/lib
2023-11-22T00:24:53.2005534Z   ACCESS_TOKEN: ***
2023-11-22T00:24:53.2006048Z   GITHUB_TOKEN: ***
2023-11-22T00:24:53.2006383Z   EXCLUDED: 
2023-11-22T00:24:53.2006796Z   EXCLUDED_LANGS: 
2023-11-22T00:24:53.2007148Z   EXCLUDE_FORKED_REPOS: true
2023-11-22T00:24:53.2007656Z ##[endgroup]
2023-11-22T00:24:53.2101891Z Python 3.8.18
2023-11-22T00:25:40.0562694Z A path returned 202. Retrying...
2023-11-22T00:25:40.0563977Z A path returned 202. Retrying...
2023-11-22T00:25:40.0567309Z A path returned 202. Retrying...
2023-11-22T00:25:40.0568209Z A path returned 202. Retrying...
2023-11-22T00:25:40.0569122Z A path returned 202. Retrying...
2023-11-22T00:25:40.0570446Z A path returned 202. Retrying...
2023-11-22T00:25:40.0571107Z A path returned 202. Retrying...
2023-11-22T00:25:40.1048284Z Traceback (most recent call last):
2023-11-22T00:25:40.1063367Z   File "generate_images.py", line 136, in <module>
2023-11-22T00:25:40.1064282Z     asyncio.run(main())
2023-11-22T00:25:40.1065373Z   File "/opt/hostedtoolcache/Python/3.8.18/x64/lib/python3.8/asyncio/runners.py", line 44, in run
2023-11-22T00:25:40.1066703Z     return loop.run_until_complete(main)
2023-11-22T00:25:40.1068102Z   File "/opt/hostedtoolcache/Python/3.8.18/x64/lib/python3.8/asyncio/base_events.py", line 616, in run_until_complete
2023-11-22T00:25:40.1069356Z     return future.result()
2023-11-22T00:25:40.1070023Z   File "generate_images.py", line 132, in main
2023-11-22T00:25:40.1071046Z     await asyncio.gather(generate_languages(s), generate_overview(s))
2023-11-22T00:25:40.1072075Z   File "generate_images.py", line 42, in generate_overview
2023-11-22T00:25:40.1073109Z     changed = (await s.lines_changed)[0] + (await s.lines_changed)[1]
2023-11-22T00:25:40.1074400Z   File "/home/runner/work/GitHub_Stats_A/GitHub_Stats_A/github_stats.py", line 486, in lines_changed
2023-11-22T00:25:40.1075484Z     for repo in await self.repos:
2023-11-22T00:25:40.1076268Z RuntimeError: Set changed size during iteration
2023-11-22T00:25:40.1247652Z ##[error]Process completed with exit code 1.
