2023-05-28T01:50:56.7191308Z ##[group]Run python3 --version
2023-05-28T01:50:56.7191683Z [36;1mpython3 --version[0m
2023-05-28T01:50:56.7191995Z [36;1mpython3 generate_images.py[0m
2023-05-28T01:50:56.7253249Z shell: /usr/bin/bash -e {0}
2023-05-28T01:50:56.7253541Z env:
2023-05-28T01:50:56.7253879Z   pythonLocation: /opt/hostedtoolcache/Python/3.8.16/x64
2023-05-28T01:50:56.7254320Z   PKG_CONFIG_PATH: /opt/hostedtoolcache/Python/3.8.16/x64/lib/pkgconfig
2023-05-28T01:50:56.7254963Z   Python_ROOT_DIR: /opt/hostedtoolcache/Python/3.8.16/x64
2023-05-28T01:50:56.7255367Z   Python2_ROOT_DIR: /opt/hostedtoolcache/Python/3.8.16/x64
2023-05-28T01:50:56.7255764Z   Python3_ROOT_DIR: /opt/hostedtoolcache/Python/3.8.16/x64
2023-05-28T01:50:56.7256193Z   LD_LIBRARY_PATH: /opt/hostedtoolcache/Python/3.8.16/x64/lib
2023-05-28T01:50:56.7256782Z   ACCESS_TOKEN: ***
2023-05-28T01:50:56.7257203Z   GITHUB_TOKEN: ***
2023-05-28T01:50:56.7257465Z   EXCLUDED: 
2023-05-28T01:50:56.7257722Z   EXCLUDED_LANGS: 
2023-05-28T01:50:56.7257997Z   EXCLUDE_FORKED_REPOS: true
2023-05-28T01:50:56.7258346Z ##[endgroup]
2023-05-28T01:50:56.7366915Z Python 3.8.16
2023-05-28T01:51:31.7712666Z A path returned 202. Retrying...
2023-05-28T01:51:31.7999008Z Traceback (most recent call last):
2023-05-28T01:51:31.8049429Z   File "generate_images.py", line 136, in <module>
2023-05-28T01:51:31.8049957Z     asyncio.run(main())
2023-05-28T01:51:31.8050447Z   File "/opt/hostedtoolcache/Python/3.8.16/x64/lib/python3.8/asyncio/runners.py", line 44, in run
2023-05-28T01:51:31.8050954Z     return loop.run_until_complete(main)
2023-05-28T01:51:31.8051472Z   File "/opt/hostedtoolcache/Python/3.8.16/x64/lib/python3.8/asyncio/base_events.py", line 616, in run_until_complete
2023-05-28T01:51:31.8051922Z     return future.result()
2023-05-28T01:51:31.8052290Z   File "generate_images.py", line 132, in main
2023-05-28T01:51:31.8052707Z     await asyncio.gather(generate_languages(s), generate_overview(s))
2023-05-28T01:51:31.8053165Z   File "generate_images.py", line 42, in generate_overview
2023-05-28T01:51:31.8053611Z     changed = (await s.lines_changed)[0] + (await s.lines_changed)[1]
2023-05-28T01:51:31.8054135Z   File "/home/runner/work/GitHub_Stats_A/GitHub_Stats_A/github_stats.py", line 486, in lines_changed
2023-05-28T01:51:31.8054555Z     for repo in await self.repos:
2023-05-28T01:51:31.8054888Z RuntimeError: Set changed size during iteration
2023-05-28T01:51:31.8363592Z ##[error]Process completed with exit code 1.
