2022-12-15T01:46:26.0255748Z ##[group]Run python3 --version
2022-12-15T01:46:26.0256061Z [36;1mpython3 --version[0m
2022-12-15T01:46:26.0256319Z [36;1mpython3 generate_images.py[0m
2022-12-15T01:46:26.0309992Z shell: /usr/bin/bash -e {0}
2022-12-15T01:46:26.0310240Z env:
2022-12-15T01:46:26.0310516Z   pythonLocation: /opt/hostedtoolcache/Python/3.8.15/x64
2022-12-15T01:46:26.0310868Z   LD_LIBRARY_PATH: /opt/hostedtoolcache/Python/3.8.15/x64/lib
2022-12-15T01:46:26.0311341Z   ACCESS_TOKEN: ***
2022-12-15T01:46:26.0311686Z   GITHUB_TOKEN: ***
2022-12-15T01:46:26.0311904Z   EXCLUDED: 
2022-12-15T01:46:26.0312123Z   EXCLUDED_LANGS: 
2022-12-15T01:46:26.0312356Z   EXCLUDE_FORKED_REPOS: true
2022-12-15T01:46:26.0312600Z ##[endgroup]
2022-12-15T01:46:26.0407129Z Python 3.8.15
2022-12-15T01:46:56.0405348Z aiohttp failed for GraphQL query
2022-12-15T01:46:56.0406269Z aiohttp failed for GraphQL query
2022-12-15T01:46:56.0407042Z aiohttp failed for GraphQL query
2022-12-15T01:46:56.0552998Z Traceback (most recent call last):
2022-12-15T01:46:56.0565623Z   File "generate_images.py", line 136, in <module>
2022-12-15T01:46:56.0566024Z     asyncio.run(main())
2022-12-15T01:46:56.0566435Z   File "/opt/hostedtoolcache/Python/3.8.15/x64/lib/python3.8/asyncio/runners.py", line 44, in run
2022-12-15T01:46:56.0566810Z     return loop.run_until_complete(main)
2022-12-15T01:46:56.0567240Z   File "/opt/hostedtoolcache/Python/3.8.15/x64/lib/python3.8/asyncio/base_events.py", line 616, in run_until_complete
2022-12-15T01:46:56.0567597Z     return future.result()
2022-12-15T01:46:56.0567897Z   File "generate_images.py", line 132, in main
2022-12-15T01:46:56.0568263Z     await asyncio.gather(generate_languages(s), generate_overview(s))
2022-12-15T01:46:56.0568942Z   File "generate_images.py", line 38, in generate_overview
2022-12-15T01:46:56.0569259Z     output = re.sub("{{ name }}", await s.name, output)
2022-12-15T01:46:56.0569651Z   File "/home/runner/work/GitHub_Stats_A/GitHub_Stats_A/github_stats.py", line 390, in name
2022-12-15T01:46:56.0569978Z     await self.get_stats()
2022-12-15T01:46:56.0570349Z   File "/home/runner/work/GitHub_Stats_A/GitHub_Stats_A/github_stats.py", line 319, in get_stats
2022-12-15T01:46:56.0570747Z     self._name = raw_results.get("data", {}).get("viewer", {}).get("name", None)
2022-12-15T01:46:56.0571363Z AttributeError: 'NoneType' object has no attribute 'get'
2022-12-15T01:46:56.0853778Z ##[error]Process completed with exit code 1.
