2023-01-30T01:24:03.0773390Z ##[group]Run python3 --version
2023-01-30T01:24:03.0773670Z [36;1mpython3 --version[0m
2023-01-30T01:24:03.0773897Z [36;1mpython3 generate_images.py[0m
2023-01-30T01:24:03.0825907Z shell: /usr/bin/bash -e {0}
2023-01-30T01:24:03.0826130Z env:
2023-01-30T01:24:03.0826388Z   pythonLocation: /opt/hostedtoolcache/Python/3.8.16/x64
2023-01-30T01:24:03.0826732Z   PKG_CONFIG_PATH: /opt/hostedtoolcache/Python/3.8.16/x64/lib/pkgconfig
2023-01-30T01:24:03.0827066Z   Python_ROOT_DIR: /opt/hostedtoolcache/Python/3.8.16/x64
2023-01-30T01:24:03.0827371Z   Python2_ROOT_DIR: /opt/hostedtoolcache/Python/3.8.16/x64
2023-01-30T01:24:03.0827672Z   Python3_ROOT_DIR: /opt/hostedtoolcache/Python/3.8.16/x64
2023-01-30T01:24:03.0827962Z   LD_LIBRARY_PATH: /opt/hostedtoolcache/Python/3.8.16/x64/lib
2023-01-30T01:24:03.0828387Z   ACCESS_TOKEN: ***
2023-01-30T01:24:03.0828697Z   GITHUB_TOKEN: ***
2023-01-30T01:24:03.0828886Z   EXCLUDED: 
2023-01-30T01:24:03.0829075Z   EXCLUDED_LANGS: 
2023-01-30T01:24:03.0829274Z   EXCLUDE_FORKED_REPOS: true
2023-01-30T01:24:03.0829524Z ##[endgroup]
2023-01-30T01:24:03.0915263Z Python 3.8.16
2023-01-30T01:24:31.4325071Z unhandled exception during asyncio.run() shutdown
2023-01-30T01:24:31.4370555Z task: <Task finished name='Task-3' coro=<generate_overview() done, defined at generate_images.py:30> exception=AttributeError("'NoneType' object has no attribute 'get'")>
2023-01-30T01:24:31.4371106Z Traceback (most recent call last):
2023-01-30T01:24:31.4464873Z   File "/opt/hostedtoolcache/Python/3.8.16/x64/lib/python3.8/asyncio/runners.py", line 44, in run
2023-01-30T01:24:31.4465297Z     return loop.run_until_complete(main)
2023-01-30T01:24:31.4465722Z   File "/opt/hostedtoolcache/Python/3.8.16/x64/lib/python3.8/asyncio/base_events.py", line 616, in run_until_complete
2023-01-30T01:24:31.4466048Z     return future.result()
2023-01-30T01:24:31.4466336Z   File "generate_images.py", line 132, in main
2023-01-30T01:24:31.4466652Z     await asyncio.gather(generate_languages(s), generate_overview(s))
2023-01-30T01:24:31.4467280Z   File "generate_images.py", line 63, in generate_languages
2023-01-30T01:24:31.4467627Z     (await s.languages).items(), reverse=True, key=lambda t: t[1].get("size")
2023-01-30T01:24:31.4468049Z   File "/home/runner/work/GitHub_Stats_A/GitHub_Stats_A/github_stats.py", line 423, in languages
2023-01-30T01:24:31.4468344Z     await self.get_stats()
2023-01-30T01:24:31.4468686Z   File "/home/runner/work/GitHub_Stats_A/GitHub_Stats_A/github_stats.py", line 319, in get_stats
2023-01-30T01:24:31.4469054Z     self._name = raw_results.get("data", {}).get("viewer", {}).get("name", None)
2023-01-30T01:24:31.4469554Z AttributeError: 'NoneType' object has no attribute 'get'
2023-01-30T01:24:31.4469738Z 
2023-01-30T01:24:31.4469901Z During handling of the above exception, another exception occurred:
2023-01-30T01:24:31.4470103Z 
2023-01-30T01:24:31.4470199Z Traceback (most recent call last):
2023-01-30T01:24:31.4470513Z   File "generate_images.py", line 38, in generate_overview
2023-01-30T01:24:31.4470825Z     output = re.sub("{{ name }}", await s.name, output)
2023-01-30T01:24:31.4471185Z   File "/home/runner/work/GitHub_Stats_A/GitHub_Stats_A/github_stats.py", line 390, in name
2023-01-30T01:24:31.4471481Z     await self.get_stats()
2023-01-30T01:24:31.4471832Z   File "/home/runner/work/GitHub_Stats_A/GitHub_Stats_A/github_stats.py", line 319, in get_stats
2023-01-30T01:24:31.4472186Z     self._name = raw_results.get("data", {}).get("viewer", {}).get("name", None)
2023-01-30T01:24:31.4472562Z AttributeError: 'NoneType' object has no attribute 'get'
2023-01-30T01:24:31.4472871Z Traceback (most recent call last):
2023-01-30T01:24:31.4473161Z   File "generate_images.py", line 136, in <module>
2023-01-30T01:24:31.4473409Z     asyncio.run(main())
2023-01-30T01:24:31.4473741Z   File "/opt/hostedtoolcache/Python/3.8.16/x64/lib/python3.8/asyncio/runners.py", line 44, in run
2023-01-30T01:24:31.4474075Z     return loop.run_until_complete(main)
2023-01-30T01:24:31.4474472Z   File "/opt/hostedtoolcache/Python/3.8.16/x64/lib/python3.8/asyncio/base_events.py", line 616, in run_until_complete
2023-01-30T01:24:31.4474931Z     return future.result()
2023-01-30T01:24:31.4475207Z   File "generate_images.py", line 132, in main
2023-01-30T01:24:31.4475508Z     await asyncio.gather(generate_languages(s), generate_overview(s))
2023-01-30T01:24:31.4475885Z   File "generate_images.py", line 63, in generate_languages
2023-01-30T01:24:31.4476214Z     (await s.languages).items(), reverse=True, key=lambda t: t[1].get("size")
2023-01-30T01:24:31.4476610Z   File "/home/runner/work/GitHub_Stats_A/GitHub_Stats_A/github_stats.py", line 423, in languages
2023-01-30T01:24:31.4476903Z     await self.get_stats()
2023-01-30T01:24:31.4477232Z   File "/home/runner/work/GitHub_Stats_A/GitHub_Stats_A/github_stats.py", line 319, in get_stats
2023-01-30T01:24:31.4477574Z     self._name = raw_results.get("data", {}).get("viewer", {}).get("name", None)
2023-01-30T01:24:31.4477966Z AttributeError: 'NoneType' object has no attribute 'get'
2023-01-30T01:24:31.4478259Z aiohttp failed for GraphQL query
2023-01-30T01:24:31.4627981Z ##[error]Process completed with exit code 1.
